# 47. 에러 처리

- 2024.8.11

## 🏷 에러 처리의 필요성

```
- try...catch 문을 사용해 에러에 적절한 대응 가능
- 에러를 발생하지 않는 예외적인 상황이 발생할 수도 있음
```

<br />

## 🏷 try...catch...finally문

```
- finally 문 생략 가능
- catch문도 생략 가능하나 catch문이 없는 try문은 의미가 없으므로 생략하지 않음
```

```jsx
try {
	// 실행할 코드
} catch (err) {
	// 에러 발생 시 이 코드 블록의 코드 실행
} finally {
	// 에러 발생과 상관없이 반드시 한 번 실행
}
```

```
- try 코드 블록의 코드에서 에러 발생 => catch 문의 err 변수에 에러 전달 => catch 코드 블록 실행
```

<br />

## 🏷 Error 객페

| 생성자 함수    | 인스턴스                                                    |
| -------------- | ----------------------------------------------------------- |
| Error          | 일반적 에러 객체                                            |
| SyntaxError    | 자바스크립트 문법에 맞지 않는 문을 해석했을 때              |
| ReferenceError | 참조할 수 없는 식별자를 참조했을 때                         |
| TypeError      | 피연산자 또는 인수의 데이터 타입이 유효하지 않을 떄         |
| RangeError     | 숫자값의 허용 범위를 벗어났을 떄                            |
| URIError       | encodeURI 또는 decodeURI 함수에 부적절한 인수를 전달했을 때 |
| EvalError      | eval 함수에서 발생                                          |

<br />

## 🏷 throw 문

```
- 에러 객체 생성과 에러 발생은 의미가 다름
- try 코드 블록에 에러를 던지면 catch문의 에러 변수가 생성되고, 던져진 에러가 객체에 할당됨
```

```jsx
try {
	throw new Error('somthing wrong');
} catch (error) {
	console.log(error);
}
```

<br />

## 🏷 에러의 전파

```jsx
const foo = () => {
	throw Error('foo에서 발생한 에러'); // 4
};

const bar = () => {
	foo(); // 3
};

const baz = () => {
	bar(); // 2
};

try {
	baz(); // 1
} catch (err) {
	console.error(err);
}
```

```
- throw된 에러를 캐치하지 않으면 호출자 방향으로 전파됨
- 위 예제에서는 foo 실행 컨텍스트 -> bar 실행 컨텍스트 -> baz 실행 컨텍스트 -> 전역 실행 컨텍스트 순으로 전파
-
```
